2019-07-05 12:30:34,330   <frozen control>            INFO       Starting radar data collection process...
2019-07-05 12:31:47,838   <frozen control>            INFO       Starting radar data collection process...
2019-07-05 12:32:50,506   <frozen control>            INFO       Starting radar data collection process...
2019-07-05 12:32:50,538   <frozen control>            DEBUG      Input arguments are --> Namespace(collect=True, interval=0, num_scans=65535, quick=False, return_data=False, scan_data_filename='collect.prd', settings_file='radar_settings.yml')
2019-07-05 12:32:50,538   <frozen pulson440>          INFO       Reading settings from 'radar_settings.yml'...
2019-07-05 12:32:50,550   <frozen pulson440>          INFO       Read following radar settings --> {'dT_0': 10, 'range_start': 4, 'range_stop': 14, 'tx_gain_ind': 63, 'pii': 11, 'code_channel': 0, 'node_id': 1, 'persist_flag': 0, 'quick_look_num_scans': 200, 'set_config_timeout': 5, 'get_config_timeout': 1, 'scan_request_timeout': 1, 'read_scan_data_timeout': 2, 'read_residual_timeout': 5}
2019-07-05 12:32:50,551   <frozen pulson440>          DEBUG      Following radar settings being used --> {'dT_0': 10, 'range_start': 4, 'range_stop': 14, 'tx_gain_ind': 63, 'pii': 11, 'code_channel': 0, 'node_id': 1, 'persist_flag': 0, 'quick_look_num_scans': 200, 'set_config_timeout': 5, 'get_config_timeout': 1, 'scan_request_timeout': 1, 'read_packet_timeout': 1, 'read_residual_timeout': 5, 'read_scan_data_timeout': 2}
2019-07-05 12:32:50,552   <frozen pulson440>          DEBUG      Settings parsed into following configuration --> OrderedDict([('node_id', 1), ('scan_start', 36684), ('scan_stop', 106996), ('scan_res', 32), ('pii', 11), ('seg_1_samp', 0), ('seg_2_samp', 0), ('seg_3_samp', 0), ('seg_4_samp', 0), ('seg_1_int', 0), ('seg_2_int', 0), ('seg_3_int', 0), ('seg_4_int', 0), ('ant_mode', 2), ('tx_gain_ind', 63), ('code_channel', 0), ('persist_flag', 0)])
2019-07-05 12:32:50,552   <frozen pulson440>          INFO       Trying to connect to radar...
2019-07-05 12:32:50,557   <frozen control>            ERROR      Fatal error encountered!
Traceback (most recent call last):
  File "<frozen pulson440>", line 275, in connect
OSError: [WinError 10049] The requested address is not valid in its context

During handling of the above exception, another exception occurred:

Traceback (most recent call last):
  File "<frozen control>", line 160, in main
  File "<frozen pulson440>", line 279, in connect
RuntimeError: Failed to connect to radar!
2019-07-05 12:32:50,558   <frozen pulson440>          INFO       Cnnnot disconnect, no radar connected!
2019-07-05 12:40:27,717   <frozen control>            INFO       Starting radar data collection process...
2019-07-05 12:40:27,740   <frozen control>            DEBUG      Input arguments are --> Namespace(collect=True, interval=0, num_scans=65535, quick=False, return_data=False, scan_data_filename='collect.prd', settings_file='radar_settings.yml')
2019-07-05 12:40:27,740   <frozen pulson440>          INFO       Reading settings from 'radar_settings.yml'...
2019-07-05 12:40:27,749   <frozen pulson440>          INFO       Read following radar settings --> {'dT_0': 10, 'range_start': 4, 'range_stop': 14, 'tx_gain_ind': 63, 'pii': 11, 'code_channel': 0, 'node_id': 1, 'persist_flag': 0, 'quick_look_num_scans': 200, 'set_config_timeout': 5, 'get_config_timeout': 1, 'scan_request_timeout': 1, 'read_scan_data_timeout': 2, 'read_residual_timeout': 5}
2019-07-05 12:40:27,749   <frozen pulson440>          DEBUG      Following radar settings being used --> {'dT_0': 10, 'range_start': 4, 'range_stop': 14, 'tx_gain_ind': 63, 'pii': 11, 'code_channel': 0, 'node_id': 1, 'persist_flag': 0, 'quick_look_num_scans': 200, 'set_config_timeout': 5, 'get_config_timeout': 1, 'scan_request_timeout': 1, 'read_packet_timeout': 1, 'read_residual_timeout': 5, 'read_scan_data_timeout': 2}
2019-07-05 12:40:27,750   <frozen pulson440>          DEBUG      Settings parsed into following configuration --> OrderedDict([('node_id', 1), ('scan_start', 36684), ('scan_stop', 106996), ('scan_res', 32), ('pii', 11), ('seg_1_samp', 0), ('seg_2_samp', 0), ('seg_3_samp', 0), ('seg_4_samp', 0), ('seg_1_int', 0), ('seg_2_int', 0), ('seg_3_int', 0), ('seg_4_int', 0), ('ant_mode', 2), ('tx_gain_ind', 63), ('code_channel', 0), ('persist_flag', 0)])
2019-07-05 12:40:27,752   <frozen pulson440>          INFO       Trying to connect to radar...
2019-07-05 12:40:27,761   <frozen control>            ERROR      Fatal error encountered!
Traceback (most recent call last):
  File "<frozen pulson440>", line 275, in connect
OSError: [WinError 10049] The requested address is not valid in its context

During handling of the above exception, another exception occurred:

Traceback (most recent call last):
  File "<frozen control>", line 160, in main
  File "<frozen pulson440>", line 279, in connect
RuntimeError: Failed to connect to radar!
2019-07-05 12:40:27,762   <frozen pulson440>          INFO       Cnnnot disconnect, no radar connected!
